Workbook

Sheet Base Completa
A1: dia | B1: mes | C1: anio | D1: inventario_inicial_pizza | E1: entrada_pizza | F1: inventario_final_pizza | G1: venta_pizza | H1: precio_venta_pizza | I1: pizzeria
A2: 1 | B2: ENERO | C2: 2019 | D2: 81 | E2: 20 | F2: 41.75 | G2: 59.25 | H2: 32000 | I2: Terraplaza
A3: 2 | B3: ENERO | C3: 2019 | D3: 41.75 | E3: 101 | F3: 82 | G3: 60.75 | H3: 32000 | I3: Terraplaza
A4: 3 | B4: ENERO | C4: 2019 | D4: 82 | E4: NA | F4: 44 | G4: 38 | H4: 32000 | I4: Terraplaza
A5: 4 | B5: ENERO | C5: 2019 | D5: 44 | E5: 100 | F5: 102.75 | G5: 41.25 | H5: 32000 | I5: Terraplaza
A6: 5 | B6: ENERO | C6: 2019 | D6: 102.75 | E6: -49 | F6: 21 | G6: 32.75 | H6: 32000 | I6: Terraplaza
A7: 6 | B7: ENERO | C7: 2019 | D7: 21 | E7: 50 | F7: 47.25 | G7: 23.75 | H7: 32000 | I7: Terraplaza
A8: 7 | B8: ENERO | C8: 2019 | D8: 47.25 | E8: 60 | F8: 54 | G8: 53.25 | H8: 32000 | I8: Terraplaza
A9: 8 | B9: ENERO | C9: 2019 | D9: 54 | E9: 30 | F9: 30.25 | G9: 53.75 | H9: 32000 | I9: Terraplaza
A10: 9 | B10: ENERO | C10: 2019 | D10: 30.25 | E10: 150 | F10: 128 | G10: 52.25 | H10: 32000 | I10: Terraplaza
A11: 10 | B11: ENERO | C11: 2019 | D11: 128 | E11: NA | F11: 81.5 | G11: 46.5 | H11: 32000 | I11: Terraplaza
A12: 11 | B12: ENERO | C12: 2019 | D12: 81.5 | E12: NA | F12: 31 | G12: 50.5 | H12: 32000 | I12: Terraplaza
A13: 12 | B13: ENERO | C13: 2019 | D13: 31 | E13: 60 | F13: 18 | G13: 73 | H13: 32000 | I13: Terraplaza
A14: 13 | B14: ENERO | C14: 2019 | D14: 18 | E14: 70 | F14: 39.25 | G14: 48.75 | H14: 32000 | I14: Terraplaza
A15: 14 | B15: ENERO | C15: 2019 | D15: 39.25 | E15: 30 | F15: 51 | G15: 18.25 | H15: 32000 | I15: Terraplaza
A16: 15 | B16: ENERO | C16: 2019 | D16: 51 | E16: 30 | F16: 35.5 | G16: 45.5 | H16: 32000 | I16: Terraplaza
A17: 16 | B17: ENERO | C17: 2019 | D17: 35.5 | E17: 80 | F17: 65.75 | G17: 49.75 | H17: 32000 | I17: Terraplaza
A18: 17 | B18: ENERO | C18: 2019 | D18: 65.75 | E18: 80 | F18: 119 | G18: 26.75 | H18: 32000 | I18: Terraplaza
A19: 18 | B19: ENERO | C19: 2019 | D19: 119 | E19: -50 | F19: 36.25 | G19: 32.75 | H19: 32000 | I19: Terraplaza
A20: 19 | B20: ENERO | C20: 2019 | D20: 36.25 | E20: 100 | F20: 84 | G20: 52.25 | H20: 32000 | I20: Terraplaza
A21: 20 | B21: ENERO | C21: 2019 | D21: 84 | E21: NA | F21: 23 | G21: 61 | H21: 32000 | I21: Terraplaza
A22: 21 | B22: ENERO | C22: 2019 | D22: 23 | E22: 120 | F22: 124 | G22: 19 | H22: 32000 | I22: Terraplaza
A23: 22 | B23: ENERO | C23: 2019 | D23: 124 | E23: NA | F23: 94.875 | G23: 29.125 | H23: 32000 | I23: Terraplaza
A24: 23 | B24: ENERO | C24: 2019 | D24: 94.875 | E24: NA | F24: 70 | G24: 24.875 | H24: 32000 | I24: Terraplaza
A25: 24 | B25: ENERO | C25: 2019 | D25: 70 | E25: 120 | F25: 175 | G25: 15 | H25: 32000 | I25: Terraplaza
A26: 25 | B26: ENERO | C26: 2019 | D26: 175 | E26: NA | F26: 158 | G26: 17 | H26: 32000 | I26: Terraplaza
A27: 26 | B27: SEPTIEMBRE | C27: 2019 | D27: 158 | E27: NA | F27: 105 | G27: 53 | H27: 32000 | I27: Terraplaza
A28: 27 | B28: ENERO | C28: 2019 | D28: 105 | E28: NA | F28: 67.625 | G28: 37.375 | H28: 32000 | I28: Terraplaza
A29: 28 | B29: ENERO | C29: 2019 | D29: 67.625 | E29: 50 | F29: 103 | G29: 14.625 | H29: 32000 | I29: Terraplaza
A30: 29 | B30: ENERO | C30: 2019 | D30: 103 | E30: NA | F30: 75.75 | G30: 27.25 | H30: 32000 | I30: Terraplaza
A31: 30 | B31: ENERO | C31: 2019 | D31: 75.75 | E31: NA | F31: 56 | G31: 19.75 | H31: 32000 | I31: Terraplaza
A32: 31 | B32: ENERO | C32: 2019 | D32: 56 | E32: 140 | F32: 172.5 | G32: 23.5 | H32: 32000 | I32: Terraplaza
A33: 1 | B33: ENERO | C33: 2019 | D33: 111 | E33: 120 | F33: 127.5 | G33: 103.5 | H33: 32000 | I33: Torres
A34: 2 | B34: ENERO | C34: 2018 | D34: 127.5 | E34: 41 | F34: 89 | G34: 79.5 | H34: 32000 | I34: Torres
A35: 3 | B35: ENERO | C35: 2018 | D35: 89 | E35: NA | F35: 0 | G35: 89 | H35: 32000 | I35: Torres
A36: 4 | B36: ENERO | C36: 2018 | D36: 0 | E36: 70 | F36: 2.5 | G36: 67.5 | H36: 32000 | I36: Torres
A37: 5 | B37: ENERO | C37: 2018 | D37: 2.5 | E37: 100 | F37: 14 | G37: 88.5 | H37: 32000 | I37: Torres
A38: 6 | B38: ENERO | C38: 2018 | D38: 14 | E38: 95 | F38: 37 | G38: 72 | H38: 32000 | I38: Torres
A39: 7 | B39: ENERO | C39: 2018 | D39: 37 | E39: 80 | F39: 30 | G39: 87 | H39: 32000 | I39: Torres
A40: 8 | B40: ENERO | C40: 2018 | D40: 30 | E40: 154 | F40: 124 | G40: 60 | H40: 32000 | I40: Torres
...

Sheet Torres
A1: dia | B1: mes | C1: anio | D1: inventario_inicial_pizza | E1: entrada_pizza | F1: inventario_final_pizza | G1: Fecha | H1: venta_pizza | I1: precio_venta_pizza | J1: =DATE(2019,1,1) + ROW()-1 -> 43466 | K1: =VLOOKUP(J1, G:H, 2, FALSE) -> 103.5
A2: 1 | B2: ENERO | C2: 2019 | D2: 111 | E2: 120 | F2: 127.5 | G2: =DATE(C2, CHOOSE(MATCH(UPPER(B2), {"ENERO","FEBRERO","MARZO","ABRIL","MAYO","JUNIO","JULIO","AGOSTO","SEPTIEMBRE","OCTUBRE","NOVIEMBRE","DICIEMBRE"}, 0), 1,2,3,4,5,6,7,8,9,10,11,12), A2) -> 43466 | H2: 103.5 | I2: 32000 | J2: =DATE(2019,1,1) + ROW()-1 -> 43467 | K2: =VLOOKUP(J2, G:H, 2, FALSE) -> 79.5
A3: 2 | B3: ENERO | C3: 2019 | D3: 127.5 | E3: 41 | F3: 89 | G3: =DATE(C3, CHOOSE(MATCH(UPPER(B3), {"ENERO","FEBRERO","MARZO","ABRIL","MAYO","JUNIO","JULIO","AGOSTO","SEPTIEMBRE","OCTUBRE","NOVIEMBRE","DICIEMBRE"}, 0), 1,2,3,4,5,6,7,8,9,10,11,12), A3) -> 43467 | H3: 79.5 | I3: 32000 | J3: =DATE(2019,1,1) + ROW()-1 -> 43468 | K3: =VLOOKUP(J3, G:H, 2, FALSE) -> 89
A4: 3 | B4: ENERO | C4: 2019 | D4: 89 | E4: NA | F4: 0 | G4: =DATE(C4, CHOOSE(MATCH(UPPER(B4), {"ENERO","FEBRERO","MARZO","ABRIL","MAYO","JUNIO","JULIO","AGOSTO","SEPTIEMBRE","OCTUBRE","NOVIEMBRE","DICIEMBRE"}, 0), 1,2,3,4,5,6,7,8,9,10,11,12), A4) -> 43468 | H4: 89 | I4: 32000 | J4: =DATE(2019,1,1) + ROW()-1 -> 43469 | K4: =VLOOKUP(J4, G:H, 2, FALSE) -> 67.5
A5: 4 | B5: ENERO | C5: 2019 | D5: 0 | E5: 70 | F5: 2.5 | G5: =DATE(C5, CHOOSE(MATCH(UPPER(B5), {"ENERO","FEBRERO","MARZO","ABRIL","MAYO","JUNIO","JULIO","AGOSTO","SEPTIEMBRE","OCTUBRE","NOVIEMBRE","DICIEMBRE"}, 0), 1,2,3,4,5,6,7,8,9,10,11,12), A5) -> 43469 | H5: 67.5 | I5: 32000 | J5: =DATE(2019,1,1) + ROW()-1 -> 43470 | K5: =VLOOKUP(J5, G:H, 2, FALSE) -> 88.5
A6: 5 | B6: ENERO | C6: 2019 | D6: 2.5 | E6: 100 | F6: 14 | G6: =DATE(C6, CHOOSE(MATCH(UPPER(B6), {"ENERO","FEBRERO","MARZO","ABRIL","MAYO","JUNIO","JULIO","AGOSTO","SEPTIEMBRE","OCTUBRE","NOVIEMBRE","DICIEMBRE"}, 0), 1,2,3,4,5,6,7,8,9,10,11,12), A6) -> 43470 | H6: 88.5 | I6: 32000 | J6: =DATE(2019,1,1) + ROW()-1 -> 43471 | K6: =VLOOKUP(J6, G:H, 2, FALSE) -> 72
A7: 6 | B7: ENERO | C7: 2019 | D7: 14 | E7: 95 | F7: 37 | G7: =DATE(C7, CHOOSE(MATCH(UPPER(B7), {"ENERO","FEBRERO","MARZO","ABRIL","MAYO","JUNIO","JULIO","AGOSTO","SEPTIEMBRE","OCTUBRE","NOVIEMBRE","DICIEMBRE"}, 0), 1,2,3,4,5,6,7,8,9,10,11,12), A7) -> 43471 | H7: 72 | I7: 32000 | J7: =DATE(2019,1,1) + ROW()-1 -> 43472 | K7: =VLOOKUP(J7, G:H, 2, FALSE) -> 87
A8: 7 | B8: ENERO | C8: 2019 | D8: 37 | E8: 80 | F8: 30 | G8: =DATE(C8, CHOOSE(MATCH(UPPER(B8), {"ENERO","FEBRERO","MARZO","ABRIL","MAYO","JUNIO","JULIO","AGOSTO","SEPTIEMBRE","OCTUBRE","NOVIEMBRE","DICIEMBRE"}, 0), 1,2,3,4,5,6,7,8,9,10,11,12), A8) -> 43472 | H8: 87 | I8: 32000 | J8: =DATE(2019,1,1) + ROW()-1 -> 43473 | K8: =VLOOKUP(J8, G:H, 2, FALSE) -> 60
A9: 8 | B9: ENERO | C9: 2019 | D9: 30 | E9: 154 | F9: 124 | G9: =DATE(C9, CHOOSE(MATCH(UPPER(B9), {"ENERO","FEBRERO","MARZO","ABRIL","MAYO","JUNIO","JULIO","AGOSTO","SEPTIEMBRE","OCTUBRE","NOVIEMBRE","DICIEMBRE"}, 0), 1,2,3,4,5,6,7,8,9,10,11,12), A9) -> 43473 | H9: 60 | I9: 32000 | J9: =DATE(2019,1,1) + ROW()-1 -> 43474 | K9: =VLOOKUP(J9, G:H, 2, FALSE) -> 62
A10: 9 | B10: ENERO | C10: 2019 | D10: 124 | E10: -46 | F10: 16 | G10: =DATE(C10, CHOOSE(MATCH(UPPER(B10), {"ENERO","FEBRERO","MARZO","ABRIL","MAYO","JUNIO","JULIO","AGOSTO","SEPTIEMBRE","OCTUBRE","NOVIEMBRE","DICIEMBRE"}, 0), 1,2,3,4,5,6,7,8,9,10,11,12), A10) -> 43474 | H10: 62 | I10: 32000 | J10: =DATE(2019,1,1) + ROW()-1 -> 43475 | K10: =VLOOKUP(J10, G:H, 2, FALSE) -> 60
A11: 10 | B11: ENERO | C11: 2019 | D11: 16 | E11: 106 | F11: 62 | G11: =DATE(C11, CHOOSE(MATCH(UPPER(B11), {"ENERO","FEBRERO","MARZO","ABRIL","MAYO","JUNIO","JULIO","AGOSTO","SEPTIEMBRE","OCTUBRE","NOVIEMBRE","DICIEMBRE"}, 0), 1,2,3,4,5,6,7,8,9,10,11,12), A11) -> 43475 | H11: 60 | I11: 32000 | J11: =DATE(2019,1,1) + ROW()-1 -> 43476 | K11: =VLOOKUP(J11, G:H, 2, FALSE) -> 72.5
A12: 11 | B12: ENERO | C12: 2019 | D12: 62 | E12: 71 | F12: 60.5 | G12: =DATE(C12, CHOOSE(MATCH(UPPER(B12), {"ENERO","FEBRERO","MARZO","ABRIL","MAYO","JUNIO","JULIO","AGOSTO","SEPTIEMBRE","OCTUBRE","NOVIEMBRE","DICIEMBRE"}, 0), 1,2,3,4,5,6,7,8,9,10,11,12), A12) -> 43476 | H12: 72.5 | I12: 32000 | J12: =DATE(2019,1,1) + ROW()-1 -> 43477 | K12: =VLOOKUP(J12, G:H, 2, FALSE) -> 72.5
A13: 12 | B13: ENERO | C13: 2019 | D13: 60.5 | E13: 81 | F13: 69 | G13: =DATE(C13, CHOOSE(MATCH(UPPER(B13), {"ENERO","FEBRERO","MARZO","ABRIL","MAYO","JUNIO","JULIO","AGOSTO","SEPTIEMBRE","OCTUBRE","NOVIEMBRE","DICIEMBRE"}, 0), 1,2,3,4,5,6,7,8,9,10,11,12), A13) -> 43477 | H13: 72.5 | I13: 32000 | J13: =DATE(2019,1,1) + ROW()-1 -> 43478 | K13: =VLOOKUP(J13, G:H, 2, FALSE) -> 83.5
A14: 13 | B14: ENERO | C14: 2019 | D14: 69 | E14: 72 | F14: 57.5 | G14: =DATE(C14, CHOOSE(MATCH(UPPER(B14), {"ENERO","FEBRERO","MARZO","ABRIL","MAYO","JUNIO","JULIO","AGOSTO","SEPTIEMBRE","OCTUBRE","NOVIEMBRE","DICIEMBRE"}, 0), 1,2,3,4,5,6,7,8,9,10,11,12), A14) -> 43478 | H14: 83.5 | I14: 32000 | J14: =DATE(2019,1,1) + ROW()-1 -> 43479 | K14: =VLOOKUP(J14, G:H, 2, FALSE) -> 58
A15: 14 | B15: ENERO | C15: 2019 | D15: 57.5 | E15: 112 | F15: 111.5 | G15: =DATE(C15, CHOOSE(MATCH(UPPER(B15), {"ENERO","FEBRERO","MARZO","ABRIL","MAYO","JUNIO","JULIO","AGOSTO","SEPTIEMBRE","OCTUBRE","NOVIEMBRE","DICIEMBRE"}, 0), 1,2,3,4,5,6,7,8,9,10,11,12), A15) -> 43479 | H15: 58 | I15: 32000 | J15: =DATE(2019,1,1) + ROW()-1 -> 43480 | K15: =VLOOKUP(J15, G:H, 2, FALSE) -> 59
A16: 15 | B16: ENERO | C16: 2019 | D16: 111.5 | E16: -30 | F16: 22.5 | G16: =DATE(C16, CHOOSE(MATCH(UPPER(B16), {"ENERO","FEBRERO","MARZO","ABRIL","MAYO","JUNIO","JULIO","AGOSTO","SEPTIEMBRE","OCTUBRE","NOVIEMBRE","DICIEMBRE"}, 0), 1,2,3,4,5,6,7,8,9,10,11,12), A16) -> 43480 | H16: 59 | I16: 32000 | J16: =DATE(2019,1,1) + ROW()-1 -> 43481 | K16: =VLOOKUP(J16, G:H, 2, FALSE) -> 62
... A18: 17 | B18: ENERO | C18: 2019 | D18: 22.5 | E18: 64 | F18: 42 | G18: =DATE(C18, CHOOSE(MATCH(UPPER(B18), {"ENERO","FEBRERO","MARZO","ABRIL","MAYO","JUNIO","JULIO","AGOSTO","SEPTIEMBRE","OCTUBRE","NOVIEMBRE","DICIEMBRE"}, 0), 1,2,3,4,5,6,7,8,9,10,11,12), A18) -> 43482 | H18: 44.5 | I18: 32000 | J18: =DATE(2019,1,1) + ROW()-1 -> 43483 | K18: =VLOOKUP(J18, G:H, 2, FALSE) -> 0
A19: 18 | B19: ENERO | C19: 2019 | D19: NA | E19: NA | F19: NA | G19: =DATE(C19, CHOOSE(MATCH(UPPER(B19), {"ENERO","FEBRERO","MARZO","ABRIL","MAYO","JUNIO","JULIO","AGOSTO","SEPTIEMBRE","OCTUBRE","NOVIEMBRE","DICIEMBRE"}, 0), 1,2,3,4,5,6,7,8,9,10,11,12), A19) -> 43483 | H19: 0 | I19: NA | J19: =DATE(2019,1,1) + ROW()-1 -> 43484 | K19: =VLOOKUP(J19, G:H, 2, FALSE) -> 100.25
A20: 19 | B20: ENERO | C20: 2019 | D20: 24 | E20: 116 | F20: 39.75 | G20: =DATE(C20, CHOOSE(MATCH(UPPER(B20), {"ENERO","FEBRERO","MARZO","ABRIL","MAYO","JUNIO","JULIO","AGOSTO","SEPTIEMBRE","OCTUBRE","NOVIEMBRE","DICIEMBRE"}, 0), 1,2,3,4,5,6,7,8,9,10,11,12), A20) -> 43484 | H20: 100.25 | I20: 32000 | J20: =DATE(2019,1,1) + ROW()-1 -> 43485 | K20: =VLOOKUP(J20, G:H, 2, FALSE) -> 84.25
A21: 20 | B21: ENERO | C21: 2019 | D21: 39.75 | E21: 175 | F21: 130.5 | G21: =DATE(C21, CHOOSE(MATCH(UPPER(B21), {"ENERO","FEBRERO","MARZO","ABRIL","MAYO","JUNIO","JULIO","AGOSTO","SEPTIEMBRE","OCTUBRE","NOVIEMBRE","DICIEMBRE"}, 0), 1,2,3,4,5,6,7,8,9,10,11,12), A21) -> 43485 | H21: 84.25 | I21: 32000 | J21: =DATE(2019,1,1) + ROW()-1 -> 43486 | K21: =VLOOKUP(J21, G:H, 2, FALSE) -> 57
A22: 21 | B22: ENERO | C22: 2019 | D22: 130.5 | E22: -15 | F22: 58.5 | G22: =DATE(C22, CHOOSE(MATCH(UPPER(B22), {"ENERO","FEBRERO","MARZO","ABRIL","MAYO","JUNIO","JULIO","AGOSTO","SEPTIEMBRE","OCTUBRE","NOVIEMBRE","DICIEMBRE"}, 0), 1,2,3,4,5,6,7,8,9,10,11,12), A22) -> 43486 | H22: 57 | I22: 32000 | J22: =DATE(2019,1,1) + ROW()-1 -> 43487 | K22: =VLOOKUP(J22, G:H, 2, FALSE) -> 45.5
A23: 22 | B23: ENERO | C23: 2019 | D23: 58.5 | E23: 175 | F23: 188 | G23: =DATE(C23, CHOOSE(MATCH(UPPER(B23), {"ENERO","FEBRERO","MARZO","ABRIL","MAYO","JUNIO","JULIO","AGOSTO","SEPTIEMBRE","OCTUBRE","NOVIEMBRE","DICIEMBRE"}, 0), 1,2,3,4,5,6,7,8,9,10,11,12), A23) -> 43487 | H23: 45.5 | I23: 32000 | J23: =DATE(2019,1,1) + ROW()-1 -> 43488 | K23: =VLOOKUP(J23, G:H, 2, FALSE) -> 50
A24: 23 | B24: ENERO | C24: 2019 | D24: 188 | E24: NA | F24: 138 | G24: =DATE(C24, CHOOSE(MATCH(UPPER(B24), {"ENERO","FEBRERO","MARZO","ABRIL","MAYO","JUNIO","JULIO","AGOSTO","SEPTIEMBRE","OCTUBRE","NOVIEMBRE","DICIEMBRE"}, 0), 1,2,3,4,5,6,7,8,9,10,11,12), A24) -> 43488 | H24: 50 | I24: 32000 | J24: =DATE(2019,1,1) + ROW()-1 -> 43489 | K24: =VLOOKUP(J24, G:H, 2, FALSE) -> 42.5
A25: 24 | B25: ENERO | C25: 2019 | D25: 138 | E25: 57 | F25: 152.5 | G25: =DATE(C25, CHOOSE(MATCH(UPPER(B25), {"ENERO","FEBRERO","MARZO","ABRIL","MAYO","JUNIO","JULIO","AGOSTO","SEPTIEMBRE","OCTUBRE","NOVIEMBRE","DICIEMBRE"}, 0), 1,2,3,4,5,6,7,8,9,10,11,12), A25) -> 43489 | H25: 42.5 | I25: 32000 | J25: =DATE(2019,1,1) + ROW()-1 -> 43490 | K25: =VLOOKUP(J25, G:H, 2, FALSE) -> 62.75
A26: 25 | B26: ENERO | C26: 2019 | D26: 152.5 | E26: NA | F26: 89.75 | G26: =DATE(C26, CHOOSE(MATCH(UPPER(B26), {"ENERO","FEBRERO","MARZO","ABRIL","MAYO","JUNIO","JULIO","AGOSTO","SEPTIEMBRE","OCTUBRE","NOVIEMBRE","DICIEMBRE"}, 0), 1,2,3,4,5,6,7,8,9,10,11,12), A26) -> 43490 | H26: 62.75 | I26: 32000 | J26: =DATE(2019,1,1) + ROW()-1 -> 43491 | K26: =VLOOKUP(J26, G:H, 2, FALSE) -> 72.75
A27: 26 | B27: ENERO | C27: 2019 | D27: 89.75 | E27: 105 | F27: 122 | G27: =DATE(C27, CHOOSE(MATCH(UPPER(B27), {"ENERO","FEBRERO","MARZO","ABRIL","MAYO","JUNIO","JULIO","AGOSTO","SEPTIEMBRE","OCTUBRE","NOVIEMBRE","DICIEMBRE"}, 0), 1,2,3,4,5,6,7,8,9,10,11,12), A27) -> 43491 | H27: 72.75 | I27: 32000 | J27: =DATE(2019,1,1) + ROW()-1 -> 43492 | K27: =VLOOKUP(J27, G:H, 2, FALSE) -> 70
A28: 27 | B28: ENERO | C28: 2019 | D28: 122 | E28: 108 | F28: 160 | G28: =DATE(C28, CHOOSE(MATCH(UPPER(B28), {"ENERO","FEBRERO","MARZO","ABRIL","MAYO","JUNIO","JULIO","AGOSTO","SEPTIEMBRE","OCTUBRE","NOVIEMBRE","DICIEMBRE"}, 0), 1,2,3,4,5,6,7,8,9,10,11,12), A28) -> 43492 | H28: 70 | I28: 32000 | J28: =DATE(2019,1,1) + ROW()-1 -> 43493 | K28: =VLOOKUP(J28, G:H, 2, FALSE) -> 34
A29: 28 | B29: ENERO | C29: 2019 | D29: 160 | E29: 55 | F29: 181 | G29: =DATE(C29, CHOOSE(MATCH(UPPER(B29), {"ENERO","FEBRERO","MARZO","ABRIL","MAYO","JUNIO","JULIO","AGOSTO","SEPTIEMBRE","OCTUBRE","NOVIEMBRE","DICIEMBRE"}, 0), 1,2,3,4,5,6,7,8,9,10,11,12), A29) -> 43493 | H29: 34 | I29: 32000 | J29: =DATE(2019,1,1) + ROW()-1 -> 43494 | K29: =VLOOKUP(J29, G:H, 2, FALSE) -> 43
A30: 29 | B30: ENERO | C30: 2019 | D30: 181 | E30: 106 | F30: 244 | G30: =DATE(C30, CHOOSE(MATCH(UPPER(B30), {"ENERO","FEBRERO","MARZO","ABRIL","MAYO","JUNIO","JULIO","AGOSTO","SEPTIEMBRE","OCTUBRE","NOVIEMBRE","DICIEMBRE"}, 0), 1,2,3,4,5,6,7,8,9,10,11,12), A30) -> 43494 | H30: 43 | I30: 32000 | J30: =DATE(2019,1,1) + ROW()-1 -> 43495 | K30: =VLOOKUP(J30, G:H, 2, FALSE) -> 47.625
A31: 30 | B31: ENERO | C31: 2019 | D31: 244 | E31: 35 | F31: 231.375 | G31: =DATE(C31, CHOOSE(MATCH(UPPER(B31), {"ENERO","FEBRERO","MARZO","ABRIL","MAYO","JUNIO","JULIO","AGOSTO","SEPTIEMBRE","OCTUBRE","NOVIEMBRE","DICIEMBRE"}, 0), 1,2,3,4,5,6,7,8,9,10,11,12), A31) -> 43495 | H31: 47.625 | I31: 32000 | J31: =DATE(2019,1,1) + ROW()-1 -> 43496 | K31: =VLOOKUP(J31, G:H, 2, FALSE) -> 68.875
A32: 31 | B32: ENERO | C32: 2019 | D32: 231.375 | E32: -103 | F32: 59.5 | G32: =DATE(C32, CHOOSE(MATCH(UPPER(B32), {"ENERO","FEBRERO","MARZO","ABRIL","MAYO","JUNIO","JULIO","AGOSTO","SEPTIEMBRE","OCTUBRE","NOVIEMBRE","DICIEMBRE"}, 0), 1,2,3,4,5,6,7,8,9,10,11,12), A32) -> 43496 | H32: 68.875 | I32: 32000 | J32: =DATE(2019,1,1) + ROW()-1 -> 43497 | K32: =VLOOKUP(J32, G:H, 2, FALSE) -> 83
A33: 1 | B33: FEBRERO | C33: 2019 | D33: 59.5 | E33: 70 | F33: 46.5 | G33: =DATE(C33, CHOOSE(MATCH(UPPER(B33), {"ENERO","FEBRERO","MARZO","ABRIL","MAYO","JUNIO","JULIO","AGOSTO","SEPTIEMBRE","OCTUBRE","NOVIEMBRE","DICIEMBRE"}, 0), 1,2,3,4,5,6,7,8,9,10,11,12), A33) -> 43497 | H33: 83 | I33: 32000 | J33: =DATE(2019,1,1) + ROW()-1 -> 43498 | K33: =VLOOKUP(J33, G:H, 2, FALSE) -> 77
A34: 2 | B34: FEBRERO | C34: 2019 | D34: 46.5 | E34: 105 | F34: 74.5 | G34: =DATE(C34, CHOOSE(MATCH(UPPER(B34), {"ENERO","FEBRERO","MARZO","ABRIL","MAYO","JUNIO","JULIO","AGOSTO","SEPTIEMBRE","OCTUBRE","NOVIEMBRE","DICIEMBRE"}, 0), 1,2,3,4,5,6,7,8,9,10,11,12), A34) -> 43498 | H34: 77 | I34: 32000 | J34: =DATE(2019,1,1) + ROW()-1 -> 43499 | K34: =VLOOKUP(J34, G:H, 2, FALSE) -> 101.5
A35: 3 | B35: FEBRERO | C35: 2019 | D35: 74.5 | E35: 73 | F35: 46 | G35: =DATE(C35, CHOOSE(MATCH(UPPER(B35), {"ENERO","FEBRERO","MARZO","ABRIL","MAYO","JUNIO","JULIO","AGOSTO","SEPTIEMBRE","OCTUBRE","NOVIEMBRE","DICIEMBRE"}, 0), 1,2,3,4,5,6,7,8,9,10,11,12), A35) -> 43499 | H35: 101.5 | I35: 32000 | J35: =DATE(2019,1,1) + ROW()-1 -> 43500 | K35: =VLOOKUP(J35, G:H, 2, FALSE) -> 46.75
A36: 4 | B36: FEBRERO | C36: 2019 | D36: 46 | E36: 20 | F36: 19.25 | G36: =DATE(C36, CHOOSE(MATCH(UPPER(B36), {"ENERO","FEBRERO","MARZO","ABRIL","MAYO","JUNIO","JULIO","AGOSTO","SEPTIEMBRE","OCTUBRE","NOVIEMBRE","DICIEMBRE"}, 0), 1,2,3,4,5,6,7,8,9,10,11,12), A36) -> 43500 | H36: 46.75 | I36: 32000 | J36: =DATE(2019,1,1) + ROW()-1 -> 43501 | K36: =VLOOKUP(J36, G:H, 2, FALSE) -> 38.25
A37: 5 | B37: FEBRERO | C37: 2019 | D37: 19.25 | E37: 72 | F37: 53 | G37: =DATE(C37, CHOOSE(MATCH(UPPER(B37), {"ENERO","FEBRERO","MARZO","ABRIL","MAYO","JUNIO","JULIO","AGOSTO","SEPTIEMBRE","OCTUBRE","NOVIEMBRE","DICIEMBRE"}, 0), 1,2,3,4,5,6,7,8,9,10,11,12), A37) -> 43501 | H37: 38.25 | I37: 32000 | J37: =DATE(2019,1,1) + ROW()-1 -> 43502 | K37: =VLOOKUP(J37, G:H, 2, FALSE) -> 42.75
A38: 6 | B38: FEBRERO | C38: 2019 | D38: 53 | E38: NA | F38: 10.25 | G38: =DATE(C38, CHOOSE(MATCH(UPPER(B38), {"ENERO","FEBRERO","MARZO","ABRIL","MAYO","JUNIO","JULIO","AGOSTO","SEPTIEMBRE","OCTUBRE","NOVIEMBRE","DICIEMBRE"}, 0), 1,2,3,4,5,6,7,8,9,10,11,12), A38) -> 43502 | H38: 42.75 | I38: 32000 | J38: =DATE(2019,1,1) + ROW()-1 -> 43503 | K38: =VLOOKUP(J38, G:H, 2, FALSE) -> 38.25
A39: 7 | B39: FEBRERO | C39: 2019 | D39: 10.25 | E39: 70 | F39: 42 | G39: =DATE(C39, CHOOSE(MATCH(UPPER(B39), {"ENERO","FEBRERO","MARZO","ABRIL","MAYO","JUNIO","JULIO","AGOSTO","SEPTIEMBRE","OCTUBRE","NOVIEMBRE","DICIEMBRE"}, 0), 1,2,3,4,5,6,7,8,9,10,11,12), A39) -> 43503 | H39: 38.25 | I39: 32000 | J39: =DATE(2019,1,1) + ROW()-1 -> 43504 | K39: =VLOOKUP(J39, G:H, 2, FALSE) -> 70
A40: 8 | B40: FEBRERO | C40: 2019 | D40: 42 | E40: 56 | F40: 28 | G40: =DATE(C40, CHOOSE(MATCH(UPPER(B40), {"ENERO","FEBRERO","MARZO","ABRIL","MAYO","JUNIO","JULIO","AGOSTO","SEPTIEMBRE","OCTUBRE","NOVIEMBRE","DICIEMBRE"}, 0), 1,2,3,4,5,6,7,8,9,10,11,12), A40) -> 43504 | H40: 70 | I40: 32000 | J40: =DATE(2019,1,1) + ROW()-1 -> 43505 | K40: =VLOOKUP(J40, G:H, 2, FALSE) -> 87
A41: 9 | B41: FEBRERO | C41: 2019 | D41: 28 | E41: 106 | F41: 47 | G41: =DATE(C41, CHOOSE(MATCH(UPPER(B41), {"ENERO","FEBRERO","MARZO","ABRIL","MAYO","JUNIO","JULIO","AGOSTO","SEPTIEMBRE","OCTUBRE","NOVIEMBRE","DICIEMBRE"}, 0), 1,2,3,4,5,6,7,8,9,10,11,12), A41) -> 43505 | H41: 87 | I41: 32000 | J41: =DATE(2019,1,1) + ROW()-1 -> 43506 | K41: =VLOOKUP(J41, G:H, 2, FALSE) -> 78
...

Sheet San José
A1: dia | B1: mes | C1: anio | D1: inventario_inicial_pizza | E1: entrada_pizza | F1: inventario_final_pizza | G1: Fecha | H1: venta_pizza | I1: precio_venta_pizza | J1: =DATE(2019,1,1) + ROW()-1 -> 43466 | K1: =VLOOKUP(J1, G:H, 2, FALSE) -> #N/A
A2: 1 | B2: ABRIL | C2: 2021 | D2: NA | E2: 90 | F2: 44 | G2: =DATE(C2, CHOOSE(MATCH(UPPER(B2), {"ENERO","FEBRERO","MARZO","ABRIL","MAYO","JUNIO","JULIO","AGOSTO","SEPTIEMBRE","OCTUBRE","NOVIEMBRE","DICIEMBRE"}, 0), 1,2,3,4,5,6,7,8,9,10,11,12), A2) -> 44287 | H2: 46 | I2: 40000 | J2: =DATE(2019,1,1) + ROW()-1 -> 43467 | K2: =VLOOKUP(J2, G:H, 2, FALSE) -> #N/A
A3: 2 | B3: ABRIL | C3: 2021 | D3: 44 | E3: 40 | F3: 34 | G3: =DATE(C3, CHOOSE(MATCH(UPPER(B3), {"ENERO","FEBRERO","MARZO","ABRIL","MAYO","JUNIO","JULIO","AGOSTO","SEPTIEMBRE","OCTUBRE","NOVIEMBRE","DICIEMBRE"}, 0), 1,2,3,4,5,6,7,8,9,10,11,12), A3) -> 44288 | H3: 50 | I3: 40000 | J3: =DATE(2019,1,1) + ROW()-1 -> 43468 | K3: =VLOOKUP(J3, G:H, 2, FALSE) -> #N/A
A4: 3 | B4: ABRIL | C4: 2021 | D4: 34 | E4: 66 | F4: 49 | G4: =DATE(C4, CHOOSE(MATCH(UPPER(B4), {"ENERO","FEBRERO","MARZO","ABRIL","MAYO","JUNIO","JULIO","AGOSTO","SEPTIEMBRE","OCTUBRE","NOVIEMBRE","DICIEMBRE"}, 0), 1,2,3,4,5,6,7,8,9,10,11,12), A4) -> 44289 | H4: 51 | I4: 40000 | J4: =DATE(2019,1,1) + ROW()-1 -> 43469 | K4: =VLOOKUP(J4, G:H, 2, FALSE) -> #N/A
A5: 4 | B5: ABRIL | C5: 2021 | D5: 49 | E5: NA | F5: 1 | G5: =DATE(C5, CHOOSE(MATCH(UPPER(B5), {"ENERO","FEBRERO","MARZO","ABRIL","MAYO","JUNIO","JULIO","AGOSTO","SEPTIEMBRE","OCTUBRE","NOVIEMBRE","DICIEMBRE"}, 0), 1,2,3,4,5,6,7,8,9,10,11,12), A5) -> 44290 | H5: 48 | I5: 40000 | J5: =DATE(2019,1,1) + ROW()-1 -> 43470 | K5: =VLOOKUP(J5, G:H, 2, FALSE) -> #N/A
A6: 5 | B6: ABRIL | C6: 2021 | D6: 1 | E6: 30 | F6: 13.5 | G6: =DATE(C6, CHOOSE(MATCH(UPPER(B6), {"ENERO","FEBRERO","MARZO","ABRIL","MAYO","JUNIO","JULIO","AGOSTO","SEPTIEMBRE","OCTUBRE","NOVIEMBRE","DICIEMBRE"}, 0), 1,2,3,4,5,6,7,8,9,10,11,12), A6) -> 44291 | H6: 17.5 | I6: 40000 | J6: =DATE(2019,1,1) + ROW()-1 -> 43471 | K6: =VLOOKUP(J6, G:H, 2, FALSE) -> #N/A
A7: 6 | B7: ABRIL | C7: 2021 | D7: 13.5 | E7: 40 | F7: 29.5 | G7: =DATE(C7, CHOOSE(MATCH(UPPER(B7), {"ENERO","FEBRERO","MARZO","ABRIL","MAYO","JUNIO","JULIO","AGOSTO","SEPTIEMBRE","OCTUBRE","NOVIEMBRE","DICIEMBRE"}, 0), 1,2,3,4,5,6,7,8,9,10,11,12), A7) -> 44292 | H7: 24 | I7: 40000 | J7: =DATE(2019,1,1) + ROW()-1 -> 43472 | K7: =VLOOKUP(J7, G:H, 2, FALSE) -> #N/A
A8: 7 | B8: ABRIL | C8: 2021 | D8: 29.5 | E8: NA | F8: 12 | G8: =DATE(C8, CHOOSE(MATCH(UPPER(B8), {"ENERO","FEBRERO","MARZO","ABRIL","MAYO","JUNIO","JULIO","AGOSTO","SEPTIEMBRE","OCTUBRE","NOVIEMBRE","DICIEMBRE"}, 0), 1,2,3,4,5,6,7,8,9,10,11,12), A8) -> 44293 | H8: 17.5 | I8: 40000 | J8: =DATE(2019,1,1) + ROW()-1 -> 43473 | K8: =VLOOKUP(J8, G:H, 2, FALSE) -> #N/A
A9: 8 | B9: ABRIL | C9: 2021 | D9: 12 | E9: 50 | F9: 48.125 | G9: =DATE(C9, CHOOSE(MATCH(UPPER(B9), {"ENERO","FEBRERO","MARZO","ABRIL","MAYO","JUNIO","JULIO","AGOSTO","SEPTIEMBRE","OCTUBRE","NOVIEMBRE","DICIEMBRE"}, 0), 1,2,3,4,5,6,7,8,9,10,11,12), A9) -> 44294 | H9: 13.875 | I9: 40000 | J9: =DATE(2019,1,1) + ROW()-1 -> 43474 | K9: =VLOOKUP(J9, G:H, 2, FALSE) -> #N/A
A10: 9 | B10: ABRIL | C10: 2021 | D10: 48.125 | E10: 70 | F10: 93 | G10: =DATE(C10, CHOOSE(MATCH(UPPER(B10), {"ENERO","FEBRERO","MARZO","ABRIL","MAYO","JUNIO","JULIO","AGOSTO","SEPTIEMBRE","OCTUBRE","NOVIEMBRE","DICIEMBRE"}, 0), 1,2,3,4,5,6,7,8,9,10,11,12), A10) -> 44295 | H10: 25.125 | I10: 40000 | J10: =DATE(2019,1,1) + ROW()-1 -> 43475 | K10: =VLOOKUP(J10, G:H, 2, FALSE) -> #N/A
A11: 10 | B11: ABRIL | C11: 2021 | D11: 93 | E11: NA | F11: 49 | G11: =DATE(C11, CHOOSE(MATCH(UPPER(B11), {"ENERO","FEBRERO","MARZO","ABRIL","MAYO","JUNIO","JULIO","AGOSTO","SEPTIEMBRE","OCTUBRE","NOVIEMBRE","DICIEMBRE"}, 0), 1,2,3,4,5,6,7,8,9,10,11,12), A11) -> 44296 | H11: 44 | I11: 40000 | J11: =DATE(2019,1,1) + ROW()-1 -> 43476 | K11: =VLOOKUP(J11, G:H, 2, FALSE) -> #N/A
A12: 11 | B12: ABRIL | C12: 2021 | D12: 49 | E12: NA | F12: 16.5 | G12: =DATE(C12, CHOOSE(MATCH(UPPER(B12), {"ENERO","FEBRERO","MARZO","ABRIL","MAYO","JUNIO","JULIO","AGOSTO","SEPTIEMBRE","OCTUBRE","NOVIEMBRE","DICIEMBRE"}, 0), 1,2,3,4,5,6,7,8,9,10,11,12), A12) -> 44297 | H12: 32.5 | I12: 40000 | J12: =DATE(2019,1,1) + ROW()-1 -> 43477 | K12: =VLOOKUP(J12, G:H, 2, FALSE) -> #N/A
A13: 12 | B13: ABRIL | C13: 2021 | D13: 16.5 | E13: NA | F13: 3.25 | G13: =DATE(C13, CHOOSE(MATCH(UPPER(B13), {"ENERO","FEBRERO","MARZO","ABRIL","MAYO","JUNIO","JULIO","AGOSTO","SEPTIEMBRE","OCTUBRE","NOVIEMBRE","DICIEMBRE"}, 0), 1,2,3,4,5,6,7,8,9,10,11,12), A13) -> 44298 | H13: 13.25 | I13: 40000 | J13: =DATE(2019,1,1) + ROW()-1 -> 43478 | K13: =VLOOKUP(J13, G:H, 2, FALSE) -> #N/A
A14: 13 | B14: ABRIL | C14: 2021 | D14: 3.25 | E14: 20 | F14: 6 | G14: =DATE(C14, CHOOSE(MATCH(UPPER(B14), {"ENERO","FEBRERO","MARZO","ABRIL","MAYO","JUNIO","JULIO","AGOSTO","SEPTIEMBRE","OCTUBRE","NOVIEMBRE","DICIEMBRE"}, 0), 1,2,3,4,5,6,7,8,9,10,11,12), A14) -> 44299 | H14: 17.25 | I14: 40000 | J14: =DATE(2019,1,1) + ROW()-1 -> 43479 | K14: =VLOOKUP(J14, G:H, 2, FALSE) -> #N/A
A15: 14 | B15: ABRIL | C15: 2021 | D15: 6 | E15: 71 | F15: 60.5 | G15: =DATE(C15, CHOOSE(MATCH(UPPER(B15), {"ENERO","FEBRERO","MARZO","ABRIL","MAYO","JUNIO","JULIO","AGOSTO","SEPTIEMBRE","OCTUBRE","NOVIEMBRE","DICIEMBRE"}, 0), 1,2,3,4,5,6,7,8,9,10,11,12), A15) -> 44300 | H15: 16.5 | I15: 40000 | J15: =DATE(2019,1,1) + ROW()-1 -> 43480 | K15: =VLOOKUP(J15, G:H, 2, FALSE) -> #N/A
A16: 15 | B16: ABRIL | C16: 2021 | D16: 60.5 | E16: NA | F16: 40.5 | G16: =DATE(C16, CHOOSE(MATCH(UPPER(B16), {"ENERO","FEBRERO","MARZO","ABRIL","MAYO","JUNIO","JULIO","AGOSTO","SEPTIEMBRE","OCTUBRE","NOVIEMBRE","DICIEMBRE"}, 0), 1,2,3,4,5,6,7,8,9,10,11,12), A16) -> 44301 | H16: 20 | I16: 40000 | J16: =DATE(2019,1,1) + ROW()-1 -> 43481 | K16: =VLOOKUP(J16, G:H, 2, FALSE) -> #N/A
A17: 16 | B17: ABRIL | C17: 2021 | D17: 40.5 | E17: NA | F17: 21 | G17: =DATE(C17, CHOOSE(MATCH(UPPER(B17), {"ENERO","FEBRERO","MARZO","ABRIL","MAYO","JUNIO","JULIO","AGOSTO","SEPTIEMBRE","OCTUBRE","NOVIEMBRE","DICIEMBRE"}, 0), 1,2,3,4,5,6,7,8,9,10,11,12), A17) -> 44302 | H17: 19.5 | I17: 40000 | J17: =DATE(2019,1,1) + ROW()-1 -> 43482 | K17: =VLOOKUP(J17, G:H, 2, FALSE) -> #N/A
A18: 17 | B18: ABRIL | C18: 2021 | D18: 21 | E18: 68 | F18: 50 | G18: =DATE(C18, CHOOSE(MATCH(UPPER(B18), {"ENERO","FEBRERO","MARZO","ABRIL","MAYO","JUNIO","JULIO","AGOSTO","SEPTIEMBRE","OCTUBRE","NOVIEMBRE","DICIEMBRE"}, 0), 1,2,3,4,5,6,7,8,9,10,11,12), A18) -> 44303 | H18: 39 | I18: 40000 | J18: =DATE(2019,1,1) + ROW()-1 -> 43483 | K18: =VLOOKUP(J18, G:H, 2, FALSE) -> #N/A
A19: 18 | B19: ABRIL | C19: 2021 | D19: 50 | E19: NA | F19: 13.5 | G19: =DATE(C19, CHOOSE(MATCH(UPPER(B19), {"ENERO","FEBRERO","MARZO","ABRIL","MAYO","JUNIO","JULIO","AGOSTO","SEPTIEMBRE","OCTUBRE","NOVIEMBRE","DICIEMBRE"}, 0), 1,2,3,4,5,6,7,8,9,10,11,12), A19) -> 44304 | H19: 36.5 | I19: 40000 | J19: =DATE(2019,1,1) + ROW()-1 -> 43484 | K19: =VLOOKUP(J19, G:H, 2, FALSE) -> #N/A
A20: 19 | B20: ABRIL | C20: 2021 | D20: 13.5 | E20: 70 | F20: 74 | G20: =DATE(C20, CHOOSE(MATCH(UPPER(B20), {"ENERO","FEBRERO","MARZO","ABRIL","MAYO","JUNIO","JULIO","AGOSTO","SEPTIEMBRE","OCTUBRE","NOVIEMBRE","DICIEMBRE"}, 0), 1,2,3,4,5,6,7,8,9,10,11,12), A20) -> 44305 | H20: 9.5 | I20: 40000 | J20: =DATE(2019,1,1) + ROW()-1 -> 43485 | K20: =VLOOKUP(J20, G:H, 2, FALSE) -> #N/A
A21: 20 | B21: ABRIL | C21: 2021 | D21: 74 | E21: NA | F21: 56.4 | G21: =DATE(C21, CHOOSE(MATCH(UPPER(B21), {"ENERO","FEBRERO","MARZO","ABRIL","MAYO","JUNIO","JULIO","AGOSTO","SEPTIEMBRE","OCTUBRE","NOVIEMBRE","DICIEMBRE"}, 0), 1,2,3,4,5,6,7,8,9,10,11,12), A21) -> 44306 | H21: 17.6 | I21: 40000 | J21: =DATE(2019,1,1) + ROW()-1 -> 43486 | K21: =VLOOKUP(J21, G:H, 2, FALSE) -> #N/A
A22: 21 | B22: ABRIL | C22: 2021 | D22: 56.4 | E22: NA | F22: 45.5 | G22: =DATE(C22, CHOOSE(MATCH(UPPER(B22), {"ENERO","FEBRERO","MARZO","ABRIL","MAYO","JUNIO","JULIO","AGOSTO","SEPTIEMBRE","OCTUBRE","NOVIEMBRE","DICIEMBRE"}, 0), 1,2,3,4,5,6,7,8,9,10,11,12), A22) -> 44307 | H22: 10.9 | I22: 40000 | J22: =DATE(2019,1,1) + ROW()-1 -> 43487 | K22: =VLOOKUP(J22, G:H, 2, FALSE) -> #N/A
A23: 22 | B23: ABRIL | C23: 2021 | D23: 45.5 | E23: NA | F23: 21 | G23: =DATE(C23, CHOOSE(MATCH(UPPER(B23), {"ENERO","FEBRERO","MARZO","ABRIL","MAYO","JUNIO","JULIO","AGOSTO","SEPTIEMBRE","OCTUBRE","NOVIEMBRE","DICIEMBRE"}, 0), 1,2,3,4,5,6,7,8,9,10,11,12), A23) -> 44308 | H23: 24.5 | I23: 40000 | J23: =DATE(2019,1,1) + ROW()-1 -> 43488 | K23: =VLOOKUP(J23, G:H, 2, FALSE) -> #N/A
A24: 23 | B24: ABRIL | C24: 2021 | D24: 21 | E24: NA | F24: 2 | G24: =DATE(C24, CHOOSE(MATCH(UPPER(B24), {"ENERO","FEBRERO","MARZO","ABRIL","MAYO","JUNIO","JULIO","AGOSTO","SEPTIEMBRE","OCTUBRE","NOVIEMBRE","DICIEMBRE"}, 0), 1,2,3,4,5,6,7,8,9,10,11,12), A24) -> 44309 | H24: 19 | I24: 40000 | J24: =DATE(2019,1,1) + ROW()-1 -> 43489 | K24: =VLOOKUP(J24, G:H, 2, FALSE) -> #N/A
A25: 24 | B25: ABRIL | C25: 2021 | D25: 2 | E25: 55 | F25: 23 | G25: =DATE(C25, CHOOSE(MATCH(UPPER(B25), {"ENERO","FEBRERO","MARZO","ABRIL","MAYO","JUNIO","JULIO","AGOSTO","SEPTIEMBRE","OCTUBRE","NOVIEMBRE","DICIEMBRE"}, 0), 1,2,3,4,5,6,7,8,9,10,11,12), A25) -> 44310 | H25: 34 | I25: 40000 | J25: =DATE(2019,1,1) + ROW()-1 -> 43490 | K25: =VLOOKUP(J25, G:H, 2, FALSE) -> #N/A
A26: 25 | B26: ABRIL | C26: 2021 | D26: 23 | E26: 30 | F26: 19 | G26: =DATE(C26, CHOOSE(MATCH(UPPER(B26), {"ENERO","FEBRERO","MARZO","ABRIL","MAYO","JUNIO","JULIO","AGOSTO","SEPTIEMBRE","OCTUBRE","NOVIEMBRE","DICIEMBRE"}, 0), 1,2,3,4,5,6,7,8,9,10,11,12), A26) -> 44311 | H26: 34 | I26: 40000 | J26: =DATE(2019,1,1) + ROW()-1 -> 43491 | K26: =VLOOKUP(J26, G:H, 2, FALSE) -> #N/A
A27: 26 | B27: ABRIL | C27: 2021 | D27: 19 | E27: NA | F27: 11 | G27: =DATE(C27, CHOOSE(MATCH(UPPER(B27), {"ENERO","FEBRERO","MARZO","ABRIL","MAYO","JUNIO","JULIO","AGOSTO","SEPTIEMBRE","OCTUBRE","NOVIEMBRE","DICIEMBRE"}, 0), 1,2,3,4,5,6,7,8,9,10,11,12), A27) -> 44312 | H27: 8 | I27: 40000 | J27: =DATE(2019,1,1) + ROW()-1 -> 43492 | K27: =VLOOKUP(J27, G:H, 2, FALSE) -> #N/A
A28: 27 | B28: ABRIL | C28: 2021 | D28: 11 | E28: 10 | F28: 4.5 | G28: =DATE(C28, CHOOSE(MATCH(UPPER(B28), {"ENERO","FEBRERO","MARZO","ABRIL","MAYO","JUNIO","JULIO","AGOSTO","SEPTIEMBRE","OCTUBRE","NOVIEMBRE","DICIEMBRE"}, 0), 1,2,3,4,5,6,7,8,9,10,11,12), A28) -> 44313 | H28: 16.5 | I28: 40000 | J28: =DATE(2019,1,1) + ROW()-1 -> 43493 | K28: =VLOOKUP(J28, G:H, 2, FALSE) -> #N/A
A29: 28 | B29: ABRIL | C29: 2021 | D29: 4.5 | E29: 20 | F29: 23 | G29: =DATE(C29, CHOOSE(MATCH(UPPER(B29), {"ENERO","FEBRERO","MARZO","ABRIL","MAYO","JUNIO","JULIO","AGOSTO","SEPTIEMBRE","OCTUBRE","NOVIEMBRE","DICIEMBRE"}, 0), 1,2,3,4,5,6,7,8,9,10,11,12), A29) -> 44314 | H29: 1.5 | I29: 40000 | J29: =DATE(2019,1,1) + ROW()-1 -> 43494 | K29: =VLOOKUP(J29, G:H, 2, FALSE) -> #N/A
A30: 29 | B30: ABRIL | C30: 2021 | D30: 23 | E30: 50 | F30: 66.75 | G30: =DATE(C30, CHOOSE(MATCH(UPPER(B30), {"ENERO","FEBRERO","MARZO","ABRIL","MAYO","JUNIO","JULIO","AGOSTO","SEPTIEMBRE","OCTUBRE","NOVIEMBRE","DICIEMBRE"}, 0), 1,2,3,4,5,6,7,8,9,10,11,12), A30) -> 44315 | H30: 6.25 | I30: 40000 | J30: =DATE(2019,1,1) + ROW()-1 -> 43495 | K30: =VLOOKUP(J30, G:H, 2, FALSE) -> #N/A
A31: 30 | B31: ABRIL | C31: 2021 | D31: 66.75 | E31: NA | F31: 51.5 | G31: =DATE(C31, CHOOSE(MATCH(UPPER(B31), {"ENERO","FEBRERO","MARZO","ABRIL","MAYO","JUNIO","JULIO","AGOSTO","SEPTIEMBRE","OCTUBRE","NOVIEMBRE","DICIEMBRE"}, 0), 1,2,3,4,5,6,7,8,9,10,11,12), A31) -> 44316 | H31: 15.25 | I31: 40000 | J31: =DATE(2019,1,1) + ROW()-1 -> 43496 | K31: =VLOOKUP(J31, G:H, 2, FALSE) -> #N/A
A32: 1 | B32: MAYO | C32: 2021 | D32: 51.5 | E32: NA | F32: 28.625 | G32: =DATE(C32, CHOOSE(MATCH(UPPER(B32), {"ENERO","FEBRERO","MARZO","ABRIL","MAYO","JUNIO","JULIO","AGOSTO","SEPTIEMBRE","OCTUBRE","NOVIEMBRE","DICIEMBRE"}, 0), 1,2,3,4,5,6,7,8,9,10,11,12), A32) -> 44317 | H32: 22.875 | I32: 40000 | J32: =DATE(2019,1,1) + ROW()-1 -> 43497 | K32: =VLOOKUP(J32, G:H, 2, FALSE) -> #N/A
A33: 2 | B33: MAYO | C33: 2021 | D33: 28.625 | E33: 40 | F33: 36.875 | G33: =DATE(C33, CHOOSE(MATCH(UPPER(B33), {"ENERO","FEBRERO","MARZO","ABRIL","MAYO","JUNIO","JULIO","AGOSTO","SEPTIEMBRE","OCTUBRE","NOVIEMBRE","DICIEMBRE"}, 0), 1,2,3,4,5,6,7,8,9,10,11,12), A33) -> 44318 | H33: 31.75 | I33: 40000 | J33: =DATE(2019,1,1) + ROW()-1 -> 43498 | K33: =VLOOKUP(J33, G:H, 2, FALSE) -> #N/A
A34: 3 | B34: MAYO | C34: 2021 | D34: 36.875 | E34: NA | F34: 36.875 | G34: =DATE(C34, CHOOSE(MATCH(UPPER(B34), {"ENERO","FEBRERO","MARZO","ABRIL","MAYO","JUNIO","JULIO","AGOSTO","SEPTIEMBRE","OCTUBRE","NOVIEMBRE","DICIEMBRE"}, 0), 1,2,3,4,5,6,7,8,9,10,11,12), A34) -> 44319 | H34: 0 | I34: 40000 | J34: =DATE(2019,1,1) + ROW()-1 -> 43499 | K34: =VLOOKUP(J34, G:H, 2, FALSE) -> #N/A
A35: 4 | B35: MAYO | C35: 2021 | D35: 36.875 | E35: 1 | F35: 16.5 | G35: =DATE(C35, CHOOSE(MATCH(UPPER(B35), {"ENERO","FEBRERO","MARZO","ABRIL","MAYO","JUNIO","JULIO","AGOSTO","SEPTIEMBRE","OCTUBRE","NOVIEMBRE","DICIEMBRE"}, 0), 1,2,3,4,5,6,7,8,9,10,11,12), A35) -> 44320 | H35: 21.375 | I35: 40000 | J35: =DATE(2019,1,1) + ROW()-1 -> 43500 | K35: =VLOOKUP(J35, G:H, 2, FALSE) -> #N/A
A36: 5 | B36: MAYO | C36: 2021 | D36: 16.5 | E36: NA | F36: 1.875 | G36: =DATE(C36, CHOOSE(MATCH(UPPER(B36), {"ENERO","FEBRERO","MARZO","ABRIL","MAYO","JUNIO","JULIO","AGOSTO","SEPTIEMBRE","OCTUBRE","NOVIEMBRE","DICIEMBRE"}, 0), 1,2,3,4,5,6,7,8,9,10,11,12), A36) -> 44321 | H36: 14.625 | I36: 40000 | J36: =DATE(2019,1,1) + ROW()-1 -> 43501 | K36: =VLOOKUP(J36, G:H, 2, FALSE) -> #N/A
A37: 6 | B37: MAYO | C37: 2021 | D37: 1.875 | E37: 40 | F37: 22 | G37: =DATE(C37, CHOOSE(MATCH(UPPER(B37), {"ENERO","FEBRERO","MARZO","ABRIL","MAYO","JUNIO","JULIO","AGOSTO","SEPTIEMBRE","OCTUBRE","NOVIEMBRE","DICIEMBRE"}, 0), 1,2,3,4,5,6,7,8,9,10,11,12), A37) -> 44322 | H37: 19.875 | I37: 40000 | J37: =DATE(2019,1,1) + ROW()-1 -> 43502 | K37: =VLOOKUP(J37, G:H, 2, FALSE) -> #N/A
A38: 7 | B38: MAYO | C38: 2021 | D38: 22 | E38: NA | F38: 7.5 | G38: =DATE(C38, CHOOSE(MATCH(UPPER(B38), {"ENERO","FEBRERO","MARZO","ABRIL","MAYO","JUNIO","JULIO","AGOSTO","SEPTIEMBRE","OCTUBRE","NOVIEMBRE","DICIEMBRE"}, 0), 1,2,3,4,5,6,7,8,9,10,11,12), A38) -> 44323 | H38: 14.5 | I38: 40000 | J38: =DATE(2019,1,1) + ROW()-1 -> 43503 | K38: =VLOOKUP(J38, G:H, 2, FALSE) -> #N/A
A39: 8 | B39: MAYO | C39: 2021 | D39: 7.5 | E39: 50 | F39: 25 | G39: =DATE(C39, CHOOSE(MATCH(UPPER(B39), {"ENERO","FEBRERO","MARZO","ABRIL","MAYO","JUNIO","JULIO","AGOSTO","SEPTIEMBRE","OCTUBRE","NOVIEMBRE","DICIEMBRE"}, 0), 1,2,3,4,5,6,7,8,9,10,11,12), A39) -> 44324 | H39: 32.5 | I39: 40000 | J39: =DATE(2019,1,1) + ROW()-1 -> 43504 | K39: =VLOOKUP(J39, G:H, 2, FALSE) -> #N/A
A40: 9 | B40: MAYO | C40: 2021 | D40: 25 | E40: 79 | F40: 41.5 | G40: =DATE(C40, CHOOSE(MATCH(UPPER(B40), {"ENERO","FEBRERO","MARZO","ABRIL","MAYO","JUNIO","JULIO","AGOSTO","SEPTIEMBRE","OCTUBRE","NOVIEMBRE","DICIEMBRE"}, 0), 1,2,3,4,5,6,7,8,9,10,11,12), A40) -> 44325 | H40: 62.5 | I40: 40000 | J40: =DATE(2019,1,1) + ROW()-1 -> 43505 | K40: =VLOOKUP(J40, G:H, 2, FALSE) -> #N/A
...

Sheet Terraplaza
A1: dia | B1: mes | C1: anio | D1: inventario_inicial_pizza | E1: entrada_pizza | F1: inventario_final_pizza | G1: Fecha | H1: venta_pizza | I1: precio_venta_pizza | J1: =DATE(2019,1,1) + ROW()-1 -> 43466 | K1: =VLOOKUP(J1, G:H, 2, FALSE) -> 59.25
A2: 1 | B2: ENERO | C2: 2019 | D2: 81 | E2: 20 | F2: 41.75 | G2: =DATE(C2, CHOOSE(MATCH(UPPER(B2), {"ENERO","FEBRERO","MARZO","ABRIL","MAYO","JUNIO","JULIO","AGOSTO","SEPTIEMBRE","OCTUBRE","NOVIEMBRE","DICIEMBRE"}, 0), 1,2,3,4,5,6,7,8,9,10,11,12), A2) -> 43466 | H2: 59.25 | I2: 32000 | J2: =DATE(2019,1,1) + ROW()-1 -> 43467 | K2: =VLOOKUP(J2, G:H, 2, FALSE) -> 60.75
A3: 2 | B3: ENERO | C3: 2019 | D3: 41.75 | E3: 101 | F3: 82 | G3: =DATE(C3, CHOOSE(MATCH(UPPER(B3), {"ENERO","FEBRERO","MARZO","ABRIL","MAYO","JUNIO","JULIO","AGOSTO","SEPTIEMBRE","OCTUBRE","NOVIEMBRE","DICIEMBRE"}, 0), 1,2,3,4,5,6,7,8,9,10,11,12), A3) -> 43467 | H3: 60.75 | I3: 32000 | J3: =DATE(2019,1,1) + ROW()-1 -> 43468 | K3: =VLOOKUP(J3, G:H, 2, FALSE) -> 38
A4: 3 | B4: ENERO | C4: 2019 | D4: 82 | E4: NA | F4: 44 | G4: =DATE(C4, CHOOSE(MATCH(UPPER(B4), {"ENERO","FEBRERO","MARZO","ABRIL","MAYO","JUNIO","JULIO","AGOSTO","SEPTIEMBRE","OCTUBRE","NOVIEMBRE","DICIEMBRE"}, 0), 1,2,3,4,5,6,7,8,9,10,11,12), A4) -> 43468 | H4: 38 | I4: 32000 | J4: =DATE(2019,1,1) + ROW()-1 -> 43469 | K4: =VLOOKUP(J4, G:H, 2, FALSE) -> 41.25
A5: 4 | B5: ENERO | C5: 2019 | D5: 44 | E5: 100 | F5: 102.75 | G5: =DATE(C5, CHOOSE(MATCH(UPPER(B5), {"ENERO","FEBRERO","MARZO","ABRIL","MAYO","JUNIO","JULIO","AGOSTO","SEPTIEMBRE","OCTUBRE","NOVIEMBRE","DICIEMBRE"}, 0), 1,2,3,4,5,6,7,8,9,10,11,12), A5) -> 43469 | H5: 41.25 | I5: 32000 | J5: =DATE(2019,1,1) + ROW()-1 -> 43470 | K5: =VLOOKUP(J5, G:H, 2, FALSE) -> 32.75
A6: 5 | B6: ENERO | C6: 2019 | D6: 102.75 | E6: -49 | F6: 21 | G6: =DATE(C6, CHOOSE(MATCH(UPPER(B6), {"ENERO","FEBRERO","MARZO","ABRIL","MAYO","JUNIO","JULIO","AGOSTO","SEPTIEMBRE","OCTUBRE","NOVIEMBRE","DICIEMBRE"}, 0), 1,2,3,4,5,6,7,8,9,10,11,12), A6) -> 43470 | H6: 32.75 | I6: 32000 | J6: =DATE(2019,1,1) + ROW()-1 -> 43471 | K6: =VLOOKUP(J6, G:H, 2, FALSE) -> 23.75
A7: 6 | B7: ENERO | C7: 2019 | D7: 21 | E7: 50 | F7: 47.25 | G7: =DATE(C7, CHOOSE(MATCH(UPPER(B7), {"ENERO","FEBRERO","MARZO","ABRIL","MAYO","JUNIO","JULIO","AGOSTO","SEPTIEMBRE","OCTUBRE","NOVIEMBRE","DICIEMBRE"}, 0), 1,2,3,4,5,6,7,8,9,10,11,12), A7) -> 43471 | H7: 23.75 | I7: 32000 | J7: =DATE(2019,1,1) + ROW()-1 -> 43472 | K7: =VLOOKUP(J7, G:H, 2, FALSE) -> 53.25
A8: 7 | B8: ENERO | C8: 2019 | D8: 47.25 | E8: 60 | F8: 54 | G8: =DATE(C8, CHOOSE(MATCH(UPPER(B8), {"ENERO","FEBRERO","MARZO","ABRIL","MAYO","JUNIO","JULIO","AGOSTO","SEPTIEMBRE","OCTUBRE","NOVIEMBRE","DICIEMBRE"}, 0), 1,2,3,4,5,6,7,8,9,10,11,12), A8) -> 43472 | H8: 53.25 | I8: 32000 | J8: =DATE(2019,1,1) + ROW()-1 -> 43473 | K8: =VLOOKUP(J8, G:H, 2, FALSE) -> 53.75
A9: 8 | B9: ENERO | C9: 2019 | D9: 54 | E9: 30 | F9: 30.25 | G9: =DATE(C9, CHOOSE(MATCH(UPPER(B9), {"ENERO","FEBRERO","MARZO","ABRIL","MAYO","JUNIO","JULIO","AGOSTO","SEPTIEMBRE","OCTUBRE","NOVIEMBRE","DICIEMBRE"}, 0), 1,2,3,4,5,6,7,8,9,10,11,12), A9) -> 43473 | H9: 53.75 | I9: 32000 | J9: =DATE(2019,1,1) + ROW()-1 -> 43474 | K9: =VLOOKUP(J9, G:H, 2, FALSE) -> 52.25
A10: 9 | B10: ENERO | C10: 2019 | D10: 30.25 | E10: 150 | F10: 128 | G10: =DATE(C10, CHOOSE(MATCH(UPPER(B10), {"ENERO","FEBRERO","MARZO","ABRIL","MAYO","JUNIO","JULIO","AGOSTO","SEPTIEMBRE","OCTUBRE","NOVIEMBRE","DICIEMBRE"}, 0), 1,2,3,4,5,6,7,8,9,10,11,12), A10) -> 43474 | H10: 52.25 | I10: 32000 | J10: =DATE(2019,1,1) + ROW()-1 -> 43475 | K10: =VLOOKUP(J10, G:H, 2, FALSE) -> 46.5
A11: 10 | B11: ENERO | C11: 2019 | D11: 128 | E11: NA | F11: 81.5 | G11: =DATE(C11, CHOOSE(MATCH(UPPER(B11), {"ENERO","FEBRERO","MARZO","ABRIL","MAYO","JUNIO","JULIO","AGOSTO","SEPTIEMBRE","OCTUBRE","NOVIEMBRE","DICIEMBRE"}, 0), 1,2,3,4,5,6,7,8,9,10,11,12), A11) -> 43475 | H11: 46.5 | I11: 32000 | J11: =DATE(2019,1,1) + ROW()-1 -> 43476 | K11: =VLOOKUP(J11, G:H, 2, FALSE) -> 50.5
A12: 11 | B12: ENERO | C12: 2019 | D12: 81.5 | E12: NA | F12: 31 | G12: =DATE(C12, CHOOSE(MATCH(UPPER(B12), {"ENERO","FEBRERO","MARZO","ABRIL","MAYO","JUNIO","JULIO","AGOSTO","SEPTIEMBRE","OCTUBRE","NOVIEMBRE","DICIEMBRE"}, 0), 1,2,3,4,5,6,7,8,9,10,11,12), A12) -> 43476 | H12: 50.5 | I12: 32000 | J12: =DATE(2019,1,1) + ROW()-1 -> 43477 | K12: =VLOOKUP(J12, G:H, 2, FALSE) -> 73
A13: 12 | B13: ENERO | C13: 2019 | D13: 31 | E13: 60 | F13: 18 | G13: =DATE(C13, CHOOSE(MATCH(UPPER(B13), {"ENERO","FEBRERO","MARZO","ABRIL","MAYO","JUNIO","JULIO","AGOSTO","SEPTIEMBRE","OCTUBRE","NOVIEMBRE","DICIEMBRE"}, 0), 1,2,3,4,5,6,7,8,9,10,11,12), A13) -> 43477 | H13: 73 | I13: 32000 | J13: =DATE(2019,1,1) + ROW()-1 -> 43478 | K13: =VLOOKUP(J13, G:H, 2, FALSE) -> 48.75
A14: 13 | B14: ENERO | C14: 2019 | D14: 18 | E14: 70 | F14: 39.25 | G14: =DATE(C14, CHOOSE(MATCH(UPPER(B14), {"ENERO","FEBRERO","MARZO","ABRIL","MAYO","JUNIO","JULIO","AGOSTO","SEPTIEMBRE","OCTUBRE","NOVIEMBRE","DICIEMBRE"}, 0), 1,2,3,4,5,6,7,8,9,10,11,12), A14) -> 43478 | H14: 48.75 | I14: 32000 | J14: =DATE(2019,1,1) + ROW()-1 -> 43479 | K14: =VLOOKUP(J14, G:H, 2, FALSE) -> 18.25
A15: 14 | B15: ENERO | C15: 2019 | D15: 39.25 | E15: 30 | F15: 51 | G15: =DATE(C15, CHOOSE(MATCH(UPPER(B15), {"ENERO","FEBRERO","MARZO","ABRIL","MAYO","JUNIO","JULIO","AGOSTO","SEPTIEMBRE","OCTUBRE","NOVIEMBRE","DICIEMBRE"}, 0), 1,2,3,4,5,6,7,8,9,10,11,12), A15) -> 43479 | H15: 18.25 | I15: 32000 | J15: =DATE(2019,1,1) + ROW()-1 -> 43480 | K15: =VLOOKUP(J15, G:H, 2, FALSE) -> 45.5
A16: 15 | B16: ENERO | C16: 2019 | D16: 51 | E16: 30 | F16: 35.5 | G16: =DATE(C16, CHOOSE(MATCH(UPPER(B16), {"ENERO","FEBRERO","MARZO","ABRIL","MAYO","JUNIO","JULIO","AGOSTO","SEPTIEMBRE","OCTUBRE","NOVIEMBRE","DICIEMBRE"}, 0), 1,2,3,4,5,6,7,8,9,10,11,12), A16) -> 43480 | H16: 45.5 | I16: 32000 | J16: =DATE(2019,1,1) + ROW()-1 -> 43481 | K16: =VLOOKUP(J16, G:H, 2, FALSE) -> 49.75
A17: 16 | B17: ENERO | C17: 2019 | D17: 35.5 | E17: 80 | F17: 65.75 | G17: =DATE(C17, CHOOSE(MATCH(UPPER(B17), {"ENERO","FEBRERO","MARZO","ABRIL","MAYO","JUNIO","JULIO","AGOSTO","SEPTIEMBRE","OCTUBRE","NOVIEMBRE","DICIEMBRE"}, 0), 1,2,3,4,5,6,7,8,9,10,11,12), A17) -> 43481 | H17: 49.75 | I17: 32000 | J17: =DATE(2019,1,1) + ROW()-1 -> 43482 | K17: =VLOOKUP(J17, G:H, 2, FALSE) -> 26.75
A18: 17 | B18: ENERO | C18: 2019 | D18: 65.75 | E18: 80 | F18: 119 | G18: =DATE(C18, CHOOSE(MATCH(UPPER(B18), {"ENERO","FEBRERO","MARZO","ABRIL","MAYO","JUNIO","JULIO","AGOSTO","SEPTIEMBRE","OCTUBRE","NOVIEMBRE","DICIEMBRE"}, 0), 1,2,3,4,5,6,7,8,9,10,11,12), A18) -> 43482 | H18: 26.75 | I18: 32000 | J18: =DATE(2019,1,1) + ROW()-1 -> 43483 | K18: =VLOOKUP(J18, G:H, 2, FALSE) -> 32.75
A19: 18 | B19: ENERO | C19: 2019 | D19: 119 | E19: -50 | F19: 36.25 | G19: =DATE(C19, CHOOSE(MATCH(UPPER(B19), {"ENERO","FEBRERO","MARZO","ABRIL","MAYO","JUNIO","JULIO","AGOSTO","SEPTIEMBRE","OCTUBRE","NOVIEMBRE","DICIEMBRE"}, 0), 1,2,3,4,5,6,7,8,9,10,11,12), A19) -> 43483 | H19: 32.75 | I19: 32000 | J19: =DATE(2019,1,1) + ROW()-1 -> 43484 | K19: =VLOOKUP(J19, G:H, 2, FALSE) -> 52.25
A20: 19 | B20: ENERO | C20: 2019 | D20: 36.25 | E20: 100 | F20: 84 | G20: =DATE(C20, CHOOSE(MATCH(UPPER(B20), {"ENERO","FEBRERO","MARZO","ABRIL","MAYO","JUNIO","JULIO","AGOSTO","SEPTIEMBRE","OCTUBRE","NOVIEMBRE","DICIEMBRE"}, 0), 1,2,3,4,5,6,7,8,9,10,11,12), A20) -> 43484 | H20: 52.25 | I20: 32000 | J20: =DATE(2019,1,1) + ROW()-1 -> 43485 | K20: =VLOOKUP(J20, G:H, 2, FALSE) -> 61
A21: 20 | B21: ENERO | C21: 2019 | D21: 84 | E21: NA | F21: 23 | G21: =DATE(C21, CHOOSE(MATCH(UPPER(B21), {"ENERO","FEBRERO","MARZO","ABRIL","MAYO","JUNIO","JULIO","AGOSTO","SEPTIEMBRE","OCTUBRE","NOVIEMBRE","DICIEMBRE"}, 0), 1,2,3,4,5,6,7,8,9,10,11,12), A21) -> 43485 | H21: 61 | I21: 32000 | J21: =DATE(2019,1,1) + ROW()-1 -> 43486 | K21: =VLOOKUP(J21, G:H, 2, FALSE) -> 19
A22: 21 | B22: ENERO | C22: 2019 | D22: 23 | E22: 120 | F22: 124 | G22: =DATE(C22, CHOOSE(MATCH(UPPER(B22), {"ENERO","FEBRERO","MARZO","ABRIL","MAYO","JUNIO","JULIO","AGOSTO","SEPTIEMBRE","OCTUBRE","NOVIEMBRE","DICIEMBRE"}, 0), 1,2,3,4,5,6,7,8,9,10,11,12), A22) -> 43486 | H22: 19 | I22: 32000 | J22: =DATE(2019,1,1) + ROW()-1 -> 43487 | K22: =VLOOKUP(J22, G:H, 2, FALSE) -> 29.125
A23: 22 | B23: ENERO | C23: 2019 | D23: 124 | E23: NA | F23: 94.875 | G23: =DATE(C23, CHOOSE(MATCH(UPPER(B23), {"ENERO","FEBRERO","MARZO","ABRIL","MAYO","JUNIO","JULIO","AGOSTO","SEPTIEMBRE","OCTUBRE","NOVIEMBRE","DICIEMBRE"}, 0), 1,2,3,4,5,6,7,8,9,10,11,12), A23) -> 43487 | H23: 29.125 | I23: 32000 | J23: =DATE(2019,1,1) + ROW()-1 -> 43488 | K23: =VLOOKUP(J23, G:H, 2, FALSE) -> 24.875
A24: 23 | B24: ENERO | C24: 2019 | D24: 94.875 | E24: NA | F24: 70 | G24: =DATE(C24, CHOOSE(MATCH(UPPER(B24), {"ENERO","FEBRERO","MARZO","ABRIL","MAYO","JUNIO","JULIO","AGOSTO","SEPTIEMBRE","OCTUBRE","NOVIEMBRE","DICIEMBRE"}, 0), 1,2,3,4,5,6,7,8,9,10,11,12), A24) -> 43488 | H24: 24.875 | I24: 32000 | J24: =DATE(2019,1,1) + ROW()-1 -> 43489 | K24: =VLOOKUP(J24, G:H, 2, FALSE) -> 15
A25: 24 | B25: ENERO | C25: 2019 | D25: 70 | E25: 120 | F25: 175 | G25: =DATE(C25, CHOOSE(MATCH(UPPER(B25), {"ENERO","FEBRERO","MARZO","ABRIL","MAYO","JUNIO","JULIO","AGOSTO","SEPTIEMBRE","OCTUBRE","NOVIEMBRE","DICIEMBRE"}, 0), 1,2,3,4,5,6,7,8,9,10,11,12), A25) -> 43489 | H25: 15 | I25: 32000 | J25: =DATE(2019,1,1) + ROW()-1 -> 43490 | K25: =VLOOKUP(J25, G:H, 2, FALSE) -> 17
A26: 25 | B26: ENERO | C26: 2019 | D26: 175 | E26: NA | F26: 158 | G26: =DATE(C26, CHOOSE(MATCH(UPPER(B26), {"ENERO","FEBRERO","MARZO","ABRIL","MAYO","JUNIO","JULIO","AGOSTO","SEPTIEMBRE","OCTUBRE","NOVIEMBRE","DICIEMBRE"}, 0), 1,2,3,4,5,6,7,8,9,10,11,12), A26) -> 43490 | H26: 17 | I26: 32000 | J26: =DATE(2019,1,1) + ROW()-1 -> 43491 | K26: =VLOOKUP(J26, G:H, 2, FALSE) -> 53
A27: 26 | B27: ENERO | C27: 2019 | D27: 158 | E27: NA | F27: 105 | G27: =DATE(C27, CHOOSE(MATCH(UPPER(B27), {"ENERO","FEBRERO","MARZO","ABRIL","MAYO","JUNIO","JULIO","AGOSTO","SEPTIEMBRE","OCTUBRE","NOVIEMBRE","DICIEMBRE"}, 0), 1,2,3,4,5,6,7,8,9,10,11,12), A27) -> 43491 | H27: 53 | I27: 32000 | J27: =DATE(2019,1,1) + ROW()-1 -> 43492 | K27: =VLOOKUP(J27, G:H, 2, FALSE) -> 37.375
A28: 27 | B28: ENERO | C28: 2019 | D28: 105 | E28: NA | F28: 67.625 | G28: =DATE(C28, CHOOSE(MATCH(UPPER(B28), {"ENERO","FEBRERO","MARZO","ABRIL","MAYO","JUNIO","JULIO","AGOSTO","SEPTIEMBRE","OCTUBRE","NOVIEMBRE","DICIEMBRE"}, 0), 1,2,3,4,5,6,7,8,9,10,11,12), A28) -> 43492 | H28: 37.375 | I28: 32000 | J28: =DATE(2019,1,1) + ROW()-1 -> 43493 | K28: =VLOOKUP(J28, G:H, 2, FALSE) -> 14.625
A29: 28 | B29: ENERO | C29: 2019 | D29: 67.625 | E29: 50 | F29: 103 | G29: =DATE(C29, CHOOSE(MATCH(UPPER(B29), {"ENERO","FEBRERO","MARZO","ABRIL","MAYO","JUNIO","JULIO","AGOSTO","SEPTIEMBRE","OCTUBRE","NOVIEMBRE","DICIEMBRE"}, 0), 1,2,3,4,5,6,7,8,9,10,11,12), A29) -> 43493 | H29: 14.625 | I29: 32000 | J29: =DATE(2019,1,1) + ROW()-1 -> 43494 | K29: =VLOOKUP(J29, G:H, 2, FALSE) -> 27.25
A30: 29 | B30: ENERO | C30: 2019 | D30: 103 | E30: NA | F30: 75.75 | G30: =DATE(C30, CHOOSE(MATCH(UPPER(B30), {"ENERO","FEBRERO","MARZO","ABRIL","MAYO","JUNIO","JULIO","AGOSTO","SEPTIEMBRE","OCTUBRE","NOVIEMBRE","DICIEMBRE"}, 0), 1,2,3,4,5,6,7,8,9,10,11,12), A30) -> 43494 | H30: 27.25 | I30: 32000 | J30: =DATE(2019,1,1) + ROW()-1 -> 43495 | K30: =VLOOKUP(J30, G:H, 2, FALSE) -> 19.75
A31: 30 | B31: ENERO | C31: 2019 | D31: 75.75 | E31: NA | F31: 56 | G31: =DATE(C31, CHOOSE(MATCH(UPPER(B31), {"ENERO","FEBRERO","MARZO","ABRIL","MAYO","JUNIO","JULIO","AGOSTO","SEPTIEMBRE","OCTUBRE","NOVIEMBRE","DICIEMBRE"}, 0), 1,2,3,4,5,6,7,8,9,10,11,12), A31) -> 43495 | H31: 19.75 | I31: 32000 | J31: =DATE(2019,1,1) + ROW()-1 -> 43496 | K31: =VLOOKUP(J31, G:H, 2, FALSE) -> 23.5
A32: 31 | B32: ENERO | C32: 2019 | D32: 56 | E32: 140 | F32: 172.5 | G32: =DATE(C32, CHOOSE(MATCH(UPPER(B32), {"ENERO","FEBRERO","MARZO","ABRIL","MAYO","JUNIO","JULIO","AGOSTO","SEPTIEMBRE","OCTUBRE","NOVIEMBRE","DICIEMBRE"}, 0), 1,2,3,4,5,6,7,8,9,10,11,12), A32) -> 43496 | H32: 23.5 | I32: 32000 | J32: =DATE(2019,1,1) + ROW()-1 -> 43497 | K32: =VLOOKUP(J32, G:H, 2, FALSE) -> 34.5
A33: 1 | B33: FEBRERO | C33: 2019 | D33: 172.5 | E33: NA | F33: 138 | G33: =DATE(C33, CHOOSE(MATCH(UPPER(B33), {"ENERO","FEBRERO","MARZO","ABRIL","MAYO","JUNIO","JULIO","AGOSTO","SEPTIEMBRE","OCTUBRE","NOVIEMBRE","DICIEMBRE"}, 0), 1,2,3,4,5,6,7,8,9,10,11,12), A33) -> 43497 | H33: 34.5 | I33: 32000 | J33: =DATE(2019,1,1) + ROW()-1 -> 43498 | K33: =VLOOKUP(J33, G:H, 2, FALSE) -> 45.5
A34: 2 | B34: FEBRERO | C34: 2019 | D34: 138 | E34: NA | F34: 92.5 | G34: =DATE(C34, CHOOSE(MATCH(UPPER(B34), {"ENERO","FEBRERO","MARZO","ABRIL","MAYO","JUNIO","JULIO","AGOSTO","SEPTIEMBRE","OCTUBRE","NOVIEMBRE","DICIEMBRE"}, 0), 1,2,3,4,5,6,7,8,9,10,11,12), A34) -> 43498 | H34: 45.5 | I34: 32000 | J34: =DATE(2019,1,1) + ROW()-1 -> 43499 | K34: =VLOOKUP(J34, G:H, 2, FALSE) -> 43.75
A35: 3 | B35: FEBRERO | C35: 2019 | D35: 92.5 | E35: NA | F35: 48.75 | G35: =DATE(C35, CHOOSE(MATCH(UPPER(B35), {"ENERO","FEBRERO","MARZO","ABRIL","MAYO","JUNIO","JULIO","AGOSTO","SEPTIEMBRE","OCTUBRE","NOVIEMBRE","DICIEMBRE"}, 0), 1,2,3,4,5,6,7,8,9,10,11,12), A35) -> 43499 | H35: 43.75 | I35: 32000 | J35: =DATE(2019,1,1) + ROW()-1 -> 43500 | K35: =VLOOKUP(J35, G:H, 2, FALSE) -> 13
A36: 4 | B36: FEBRERO | C36: 2019 | D36: 48.75 | E36: 50 | F36: 85.75 | G36: =DATE(C36, CHOOSE(MATCH(UPPER(B36), {"ENERO","FEBRERO","MARZO","ABRIL","MAYO","JUNIO","JULIO","AGOSTO","SEPTIEMBRE","OCTUBRE","NOVIEMBRE","DICIEMBRE"}, 0), 1,2,3,4,5,6,7,8,9,10,11,12), A36) -> 43500 | H36: 13 | I36: 32000 | J36: =DATE(2019,1,1) + ROW()-1 -> 43501 | K36: =VLOOKUP(J36, G:H, 2, FALSE) -> 17.75
A37: 5 | B37: FEBRERO | C37: 2019 | D37: 85.75 | E37: NA | F37: 68 | G37: =DATE(C37, CHOOSE(MATCH(UPPER(B37), {"ENERO","FEBRERO","MARZO","ABRIL","MAYO","JUNIO","JULIO","AGOSTO","SEPTIEMBRE","OCTUBRE","NOVIEMBRE","DICIEMBRE"}, 0), 1,2,3,4,5,6,7,8,9,10,11,12), A37) -> 43501 | H37: 17.75 | I37: 32000 | J37: =DATE(2019,1,1) + ROW()-1 -> 43502 | K37: =VLOOKUP(J37, G:H, 2, FALSE) -> 22
A38: 6 | B38: FEBRERO | C38: 2019 | D38: 68 | E38: NA | F38: 46 | G38: =DATE(C38, CHOOSE(MATCH(UPPER(B38), {"ENERO","FEBRERO","MARZO","ABRIL","MAYO","JUNIO","JULIO","AGOSTO","SEPTIEMBRE","OCTUBRE","NOVIEMBRE","DICIEMBRE"}, 0), 1,2,3,4,5,6,7,8,9,10,11,12), A38) -> 43502 | H38: 22 | I38: 32000 | J38: =DATE(2019,1,1) + ROW()-1 -> 43503 | K38: =VLOOKUP(J38, G:H, 2, FALSE) -> 14.5
A39: 7 | B39: FEBRERO | C39: 2019 | D39: 46 | E39: NA | F39: 31.5 | G39: =DATE(C39, CHOOSE(MATCH(UPPER(B39), {"ENERO","FEBRERO","MARZO","ABRIL","MAYO","JUNIO","JULIO","AGOSTO","SEPTIEMBRE","OCTUBRE","NOVIEMBRE","DICIEMBRE"}, 0), 1,2,3,4,5,6,7,8,9,10,11,12), A39) -> 43503 | H39: 14.5 | I39: 32000 | J39: =DATE(2019,1,1) + ROW()-1 -> 43504 | K39: =VLOOKUP(J39, G:H, 2, FALSE) -> 29
A40: 8 | B40: FEBRERO | C40: 2019 | D40: 31.5 | E40: 120 | F40: 122.5 | G40: =DATE(C40, CHOOSE(MATCH(UPPER(B40), {"ENERO","FEBRERO","MARZO","ABRIL","MAYO","JUNIO","JULIO","AGOSTO","SEPTIEMBRE","OCTUBRE","NOVIEMBRE","DICIEMBRE"}, 0), 1,2,3,4,5,6,7,8,9,10,11,12), A40) -> 43504 | H40: 29 | I40: 32000 | J40: =DATE(2019,1,1) + ROW()-1 -> 43505 | K40: =VLOOKUP(J40, G:H, 2, FALSE) -> 33.5
...

Sheet Totales
A1: Fecha | B1: Total | C1: Terraplaza | D1: San José | E1: Torres
A2: 43466 | B2: =IFERROR(Torres!K1, 0) + IFERROR('San José'!K1, 0) + IFERROR(Terraplaza!K1, 0) -> 162.75 | C2: 59.25 | D2: #N/A | E2: 103.5
A3: 43467 | B3: =IFERROR(Torres!K2, 0) + IFERROR('San José'!K2, 0) + IFERROR(Terraplaza!K2, 0) -> 140.25 | C3: 60.75 | D3: #N/A | E3: 79.5
A4: 43468 | B4: =IFERROR(Torres!K3, 0) + IFERROR('San José'!K3, 0) + IFERROR(Terraplaza!K3, 0) -> 127 | C4: 38 | D4: #N/A | E4: 89
A5: 43469 | B5: =IFERROR(Torres!K4, 0) + IFERROR('San José'!K4, 0) + IFERROR(Terraplaza!K4, 0) -> 108.75 | C5: 41.25 | D5: #N/A | E5: 67.5
A6: 43470 | B6: =IFERROR(Torres!K5, 0) + IFERROR('San José'!K5, 0) + IFERROR(Terraplaza!K5, 0) -> 121.25 | C6: 32.75 | D6: #N/A | E6: 88.5
A7: 43471 | B7: =IFERROR(Torres!K6, 0) + IFERROR('San José'!K6, 0) + IFERROR(Terraplaza!K6, 0) -> 95.75 | C7: 23.75 | D7: #N/A | E7: 72
A8: 43472 | B8: =IFERROR(Torres!K7, 0) + IFERROR('San José'!K7, 0) + IFERROR(Terraplaza!K7, 0) -> 140.25 | C8: 53.25 | D8: #N/A | E8: 87
A9: 43473 | B9: =IFERROR(Torres!K8, 0) + IFERROR('San José'!K8, 0) + IFERROR(Terraplaza!K8, 0) -> 113.75 | C9: 53.75 | D9: #N/A | E9: 60
A10: 43474 | B10: =IFERROR(Torres!K9, 0) + IFERROR('San José'!K9, 0) + IFERROR(Terraplaza!K9, 0) -> 114.25 | C10: 52.25 | D10: #N/A | E10: 62
A11: 43475 | B11: =IFERROR(Torres!K10, 0) + IFERROR('San José'!K10, 0) + IFERROR(Terraplaza!K10, 0) -> 106.5 | C11: 46.5 | D11: #N/A | E11: 60
A12: 43476 | B12: =IFERROR(Torres!K11, 0) + IFERROR('San José'!K11, 0) + IFERROR(Terraplaza!K11, 0) -> 123 | C12: 50.5 | D12: #N/A | E12: 72.5
A13: 43477 | B13: =IFERROR(Torres!K12, 0) + IFERROR('San José'!K12, 0) + IFERROR(Terraplaza!K12, 0) -> 145.5 | C13: 73 | D13: #N/A | E13: 72.5
... A487: 43951 | B487: =IFERROR(Torres!K486, 0) + IFERROR('San José'!K486, 0) + IFERROR(Terraplaza!K486, 0) -> 39.475 | C487: 0 | D487: #N/A | E487: 39.475
A488: 43952 | B488: =IFERROR(Torres!K487, 0) + IFERROR('San José'!K487, 0) + IFERROR(Terraplaza!K487, 0) -> 31.525 | C488: #N/A | D488: #N/A | E488: 31.525
A489: 43953 | B489: =IFERROR(Torres!K488, 0) + IFERROR('San José'!K488, 0) + IFERROR(Terraplaza!K488, 0) -> 45.5 | C489: #N/A | D489: #N/A | E489: 45.5
A490: 43954 | B490: =IFERROR(Torres!K489, 0) + IFERROR('San José'!K489, 0) + IFERROR(Terraplaza!K489, 0) -> 33 | C490: #N/A | D490: #N/A | E490: 33
A491: 43955 | B491: =IFERROR(Torres!K490, 0) + IFERROR('San José'!K490, 0) + IFERROR(Terraplaza!K490, 0) -> 18.5 | C491: #N/A | D491: #N/A | E491: 18.5
A492: 43956 | B492: =IFERROR(Torres!K491, 0) + IFERROR('San José'!K491, 0) + IFERROR(Terraplaza!K491, 0) -> 14 | C492: #N/A | D492: #N/A | E492: 14
A493: 43957 | B493: =IFERROR(Torres!K492, 0) + IFERROR('San José'!K492, 0) + IFERROR(Terraplaza!K492, 0) -> 17.5 | C493: #N/A | D493: #N/A | E493: 17.5
A494: 43958 | B494: =IFERROR(Torres!K493, 0) + IFERROR('San José'!K493, 0) + IFERROR(Terraplaza!K493, 0) -> 23.5 | C494: #N/A | D494: #N/A | E494: 23.5
A495: 43959 | B495: =IFERROR(Torres!K494, 0) + IFERROR('San José'!K494, 0) + IFERROR(Terraplaza!K494, 0) -> 30 | C495: #N/A | D495: #N/A | E495: 30
A496: 43960 | B496: =IFERROR(Torres!K495, 0) + IFERROR('San José'!K495, 0) + IFERROR(Terraplaza!K495, 0) -> 38.5 | C496: #N/A | D496: #N/A | E496: 38.5
A497: 43961 | B497: =IFERROR(Torres!K496, 0) + IFERROR('San José'!K496, 0) + IFERROR(Terraplaza!K496, 0) -> 62.375 | C497: #N/A | D497: #N/A | E497: 62.375
A498: 43962 | B498: =IFERROR(Torres!K497, 0) + IFERROR('San José'!K497, 0) + IFERROR(Terraplaza!K497, 0) -> 24.625 | C498: #N/A | D498: #N/A | E498: 24.625
A499: 43963 | B499: =IFERROR(Torres!K498, 0) + IFERROR('San José'!K498, 0) + IFERROR(Terraplaza!K498, 0) -> 29.5 | C499: #N/A | D499: #N/A | E499: 29.5
... A610: 44074 | B610: =IFERROR(Torres!K609, 0) + IFERROR('San José'!K609, 0) + IFERROR(Terraplaza!K609, 0) -> 35.5 | C610: #N/A | D610: #N/A | E610: 35.5
A611: 44075 | B611: =IFERROR(Torres!K610, 0) + IFERROR('San José'!K610, 0) + IFERROR(Terraplaza!K610, 0) -> 0 | C611: #N/A | D611: #N/A | E611: #N/A
A612: 44076 | B612: =IFERROR(Torres!K611, 0) + IFERROR('San José'!K611, 0) + IFERROR(Terraplaza!K611, 0) -> 0 | C612: #N/A | D612: #N/A | E612: #N/A
A613: 44077 | B613: =IFERROR(Torres!K612, 0) + IFERROR('San José'!K612, 0) + IFERROR(Terraplaza!K612, 0) -> 0 | C613: #N/A | D613: #N/A | E613: #N/A
A614: 44078 | B614: =IFERROR(Torres!K613, 0) + IFERROR('San José'!K613, 0) + IFERROR(Terraplaza!K613, 0) -> 0 | C614: #N/A | D614: #N/A | E614: #N/A
A615: 44079 | B615: =IFERROR(Torres!K614, 0) + IFERROR('San José'!K614, 0) + IFERROR(Terraplaza!K614, 0) -> 0 | C615: #N/A | D615: #N/A | E615: #N/A
A616: 44080 | B616: =IFERROR(Torres!K615, 0) + IFERROR('San José'!K615, 0) + IFERROR(Terraplaza!K615, 0) -> 0 | C616: #N/A | D616: #N/A | E616: #N/A
A617: 44081 | B617: =IFERROR(Torres!K616, 0) + IFERROR('San José'!K616, 0) + IFERROR(Terraplaza!K616, 0) -> 0 | C617: #N/A | D617: #N/A | E617: #N/A
A618: 44082 | B618: =IFERROR(Torres!K617, 0) + IFERROR('San José'!K617, 0) + IFERROR(Terraplaza!K617, 0) -> 0 | C618: #N/A | D618: #N/A | E618: #N/A
A619: 44083 | B619: =IFERROR(Torres!K618, 0) + IFERROR('San José'!K618, 0) + IFERROR(Terraplaza!K618, 0) -> 0 | C619: #N/A | D619: #N/A | E619: #N/A
A620: 44084 | B620: =IFERROR(Torres!K619, 0) + IFERROR('San José'!K619, 0) + IFERROR(Terraplaza!K619, 0) -> 0 | C620: #N/A | D620: #N/A | E620: #N/A
A621: 44085 | B621: =IFERROR(Torres!K620, 0) + IFERROR('San José'!K620, 0) + IFERROR(Terraplaza!K620, 0) -> 0 | C621: #N/A | D621: #N/A | E621: #N/A
A622: 44086 | B622: =IFERROR(Torres!K621, 0) + IFERROR('San José'!K621, 0) + IFERROR(Terraplaza!K621, 0) -> 0 | C622: #N/A | D622: #N/A | E622: #N/A
... A640: 44104 | B640: =IFERROR(Torres!K639, 0) + IFERROR('San José'!K639, 0) + IFERROR(Terraplaza!K639, 0) -> 0 | C640: #N/A | D640: #N/A | E640: #N/A
...

Sheet Resumen
